Workbook

Sheet テーブル一覧
A1: 設計完了 | B1: No | C1: テーブル名(物理名) | D1: テーブル名(論理名) | E1: 1レコード当たりの容量[bit] | F1: 分類 | G1: 説明 | H1: 備考
A2: =IF(COUNTIFS(テーブル定義_一覧!$D:$D,$C2,テーブル定義_一覧!$A:$A,"")>0,"","〇") -> 〇 | B2: =ROW()-1 -> 1 | C2: {=_xlfn.UNIQUE(_xlfn._xlws.FILTER(テーブル定義_一覧!D:D,(テーブル定義_一覧!D:D<>"")*(テーブル定義_一覧!D:D<>"テーブル名(物理名)")))} -> vtuber_profiles | D2: =_xlfn.XLOOKUP(C2,テーブル定義_一覧!D:D,テーブル定義_一覧!E:E,"error") -> Vtuberプロフィール | E2: =SUMIF(テーブル定義_一覧!D:D,C2,テーブル定義_一覧!I:I) -> 1288 | F2: コンテンツ(動的) | G2: プロフィール本体。特に言語に依存しないIDや数値、FKが設定してあるものなど
A3: =IF(COUNTIFS(テーブル定義_一覧!$D:$D,$C3,テーブル定義_一覧!$A:$A,"")>0,"","〇") -> 〇 | B3: =ROW()-1 -> 2 | C3: join_group | D3: =_xlfn.XLOOKUP(C3,テーブル定義_一覧!D:D,テーブル定義_一覧!E:E,"error") -> 所属 | E3: =SUMIF(テーブル定義_一覧!D:D,C3,テーブル定義_一覧!I:I) -> 1416 | F3: コンテンツ(動的) | G3: Vtuberの所属を管理する。ホロライブ、にじさんじ、個人勢など
A4: =IF(COUNTIFS(テーブル定義_一覧!$D:$D,$C4,テーブル定義_一覧!$A:$A,"")>0,"","〇") -> 〇 | B4: =ROW()-1 -> 3 | C4: tag | D4: =_xlfn.XLOOKUP(C4,テーブル定義_一覧!D:D,テーブル定義_一覧!E:E,"error") -> タグ | E4: =SUMIF(テーブル定義_一覧!D:D,C4,テーブル定義_一覧!I:I) -> 776 | F4: コンテンツ(動的) | G4: ユーザーが任意でつけられるタグ。歌ってみた、ゲーム実況、ASMRなど
A5: =IF(COUNTIFS(テーブル定義_一覧!$D:$D,$C5,テーブル定義_一覧!$A:$A,"")>0,"","〇") -> 〇 | B5: =ROW()-1 -> 4 | C5: badge | D5: =_xlfn.XLOOKUP(C5,テーブル定義_一覧!D:D,テーブル定義_一覧!E:E,"error") -> バッジ | E5: =SUMIF(テーブル定義_一覧!D:D,C5,テーブル定義_一覧!I:I) -> 1160 | F5: システム管理(静的) | G5: システム的に自動で付与されるバッジを管理する。よく見られているVtuber、新人Vtuber、最近更新されたVtuberなど
A6: =IF(COUNTIFS(テーブル定義_一覧!$D:$D,$C6,テーブル定義_一覧!$A:$A,"")>0,"","〇") -> 〇 | B6: =ROW()-1 -> 5 | C6: activity_status | D6: =_xlfn.XLOOKUP(C6,テーブル定義_一覧!D:D,テーブル定義_一覧!E:E,"error") -> 活動状態 | E6: =SUMIF(テーブル定義_一覧!D:D,C6,テーブル定義_一覧!I:I) -> 904 | F6: システム管理(静的) | G6: Vtuber、所属の活動状態を管理する。準備中、活動中、休止中、卒業済みなど
A7: =IF(COUNTIFS(テーブル定義_一覧!$D:$D,$C7,テーブル定義_一覧!$A:$A,"")>0,"","〇") -> 〇 | B7: =ROW()-1 -> 6 | C7: sns_link | D7: =_xlfn.XLOOKUP(C7,テーブル定義_一覧!D:D,テーブル定義_一覧!E:E,"error") -> SNSリンク | E7: =SUMIF(テーブル定義_一覧!D:D,C7,テーブル定義_一覧!I:I) -> 1288 | F7: コンテンツ(動的) | G7: プロフィールのSNSリンクを管理する。アイコン、ラベル、URLがあるため別テーブルになった
A8: =IF(COUNTIFS(テーブル定義_一覧!$D:$D,$C8,テーブル定義_一覧!$A:$A,"")>0,"","〇") -> 〇 | B8: =ROW()-1 -> 7 | C8: bbs_res | D8: =_xlfn.XLOOKUP(C8,テーブル定義_一覧!D:D,テーブル定義_一覧!E:E,"error") -> BBS | E8: =SUMIF(テーブル定義_一覧!D:D,C8,テーブル定義_一覧!I:I) -> 1096 | F8: コンテンツ(動的) | G8: 各Vtuber詳細画面でのチャットのレスを管理。
A9: =IF(COUNTIFS(テーブル定義_一覧!$D:$D,$C9,テーブル定義_一覧!$A:$A,"")>0,"","〇") -> 〇 | B9: =ROW()-1 -> 8 | C9: page_author | D9: =_xlfn.XLOOKUP(C9,テーブル定義_一覧!D:D,テーブル定義_一覧!E:E,"error") -> ページ編集者 | E9: =SUMIF(テーブル定義_一覧!D:D,C9,テーブル定義_一覧!I:I) -> 1256 | F9: コンテンツ(動的) | G9: プロフィールの編集者を管理。編集内容も持つ。
A10: =IF(COUNTIFS(テーブル定義_一覧!$D:$D,$C10,テーブル定義_一覧!$A:$A,"")>0,"","〇") -> 〇 | B10: =ROW()-1 -> 9 | C10: contact | D10: =_xlfn.XLOOKUP(C10,テーブル定義_一覧!D:D,テーブル定義_一覧!E:E,"error") -> 問い合わせ | E10: =SUMIF(テーブル定義_一覧!D:D,C10,テーブル定義_一覧!I:I) -> 5112 | F10: コンテンツ(動的) | G10: ユーザーからの問い合わせ情報。問い合わせ内容や連絡先を管理
A11: =IF(COUNTIFS(テーブル定義_一覧!$D:$D,$C11,テーブル定義_一覧!$A:$A,"")>0,"","〇") -> 〇 | B11: =ROW()-1 -> 10 | C11: priority | D11: =_xlfn.XLOOKUP(C11,テーブル定義_一覧!D:D,テーブル定義_一覧!E:E,"error") -> 優先度 | E11: =SUMIF(テーブル定義_一覧!D:D,C11,テーブル定義_一覧!I:I) -> 904 | F11: システム管理(静的) | G11: 管理者向け。問い合わせに対する優先度を管理するためのステータス定義。最優先、優先度低など
A12: =IF(COUNTIFS(テーブル定義_一覧!$D:$D,$C12,テーブル定義_一覧!$A:$A,"")>0,"","〇") -> 〇 | B12: =ROW()-1 -> 11 | C12: response_status | D12: =_xlfn.XLOOKUP(C12,テーブル定義_一覧!D:D,テーブル定義_一覧!E:E,"error") -> 対応状況 | E12: =SUMIF(テーブル定義_一覧!D:D,C12,テーブル定義_一覧!I:I) -> 904 | F12: システム管理(静的) | G12: 管理者向け。問い合わせに対する対応状況を管理するためのステータス定義。未対応、対応中など
A13: =IF(COUNTIFS(テーブル定義_一覧!$D:$D,$C13,テーブル定義_一覧!$A:$A,"")>0,"","〇") -> 〇 | B13: =ROW()-1 -> 12 | C13: language | D13: =_xlfn.XLOOKUP(C13,テーブル定義_一覧!D:D,テーブル定義_一覧!E:E,"error") -> 表示言語 | E13: =SUMIF(テーブル定義_一覧!D:D,C13,テーブル定義_一覧!I:I) -> 1488 | F13: システム管理(静的) | G13: Webサイトが対応する言語の定義。
A14: =IF(COUNTIFS(テーブル定義_一覧!$D:$D,$C14,テーブル定義_一覧!$A:$A,"")>0,"","〇") -> 〇 | B14: =ROW()-1 -> 13 | C14: screen_word | D14: =_xlfn.XLOOKUP(C14,テーブル定義_一覧!D:D,テーブル定義_一覧!E:E,"error") -> 画面文言 | E14: =SUMIF(テーブル定義_一覧!D:D,C14,テーブル定義_一覧!I:I) -> 1032 | F14: システム管理(静的) | G14: 画面表示する単語全般やプルダウン、バッジなどの中身を定義する。表示言語ごとに用意する。画面要素x表示言語
... A28: =IF(COUNTIFS(テーブル定義_一覧!$D:$D,$C28,テーブル定義_一覧!$A:$A,"")>0,"","〇") -> 〇 | B28: =ROW()-1 -> 27 | C28: profile_activity | D28: =_xlfn.XLOOKUP(C28,テーブル定義_一覧!D:D,テーブル定義_一覧!E:E,"error") -> プロフィールの活動ジャンル | E28: =SUMIF(テーブル定義_一覧!D:D,C28,テーブル定義_一覧!I:I) -> 1032 | F28: コンテンツ(動的) | G28: プロフィールに紐づく活動ジャンルを管理する

Sheet テーブル定義_一覧
A1: 設計完了 | B1: FKリンク先検索用 | C1: No | D1: テーブル名(物理名) | E1: テーブル名(論理名) | F1: カラム名(物理名) | G1: カラム名(論理名) | H1: 型 | I1: bit数 | J1: PK | K1: FK | L1: FK参照先 | M1: FK参照先No | N1: 非NULL | O1: Unique | P1: デフォルト | Q1: 説明 | R1: 画面入力必須 | S1: 複数 | T1: 画面実装済み | U1: 備考
A2: 〇 | B2: =D2&"."&F2 -> vtuber_profiles.vtuber_profiles_uuid | C2: =ROW()-1 -> 1 | D2: vtuber_profiles | E2: Vtuberプロフィール | F2: =D2&"_uuid" -> vtuber_profiles_uuid | G2: UUID | H2: uuid | I2: =_xlfn.LET( _xlpm.可変bit数,--MID(H2,FIND("(",H2)+1,FIND(")",H2)-FIND("(",H2)-1), _xlfn.XLOOKUP( $H2, 型とバイト数!$B$3:$B$54, 型とバイト数!$E$3:$E$54, IF(LEFT($H2,7)="varchar",_xlpm.可変bit数*8, IF(LEFT($H2,4)="char",_xlpm.可変bit数*8, IF(LEFT($H2,3)="bit",_xlpm.可変bit数,"???") ) ) ) ) -> 128 | J2: x | M2: =_xlfn.SINGLE(IF(K2="","",IF(L2="","参照先未定義",_xlfn.XLOOKUP(L2,B:B,C:C,"エラー")))) | N2: x(PK制約) | O2: x(PK制約) | P2: gen_random_uuid()
A3: 〇 | B3: =D3&"."&F3 -> vtuber_profiles.vtuber_profiles_id | C3: =ROW()-1 -> 2 | D3: {=INDIRECT(ADDRESS(ROW()-1,COLUMN()))} -> vtuber_profiles | E3: {=INDIRECT(ADDRESS(ROW()-1,COLUMN()))} -> Vtuberプロフィール | F3: vtuber_profiles_id | G3: VプロフィールID | H3: varchar(8) | I3: =_xlfn.LET( _xlpm.可変bit数,--MID(H3,FIND("(",H3)+1,FIND(")",H3)-FIND("(",H3)-1), _xlfn.XLOOKUP( $H3, 型とバイト数!$B$3:$B$54, 型とバイト数!$E$3:$E$54, IF(LEFT($H3,7)="varchar",_xlpm.可変bit数*8, IF(LEFT($H3,4)="char",_xlpm.可変bit数*8, IF(LEFT($H3,3)="bit",_xlpm.可変bit数,"???") ) ) ) ) -> 64 | M3: =_xlfn.SINGLE(IF(K3="","",IF(L3="","参照先未定義",_xlfn.XLOOKUP(L3,B:B,C:C,"エラー")))) | N3: x | O3: x | U3: URLに使用する（DB連携はUUIDで管理
A4: 〇 | B4: =D4&"."&F4 -> vtuber_profiles.user_id | C4: =ROW()-1 -> 3 | D4: {=INDIRECT(ADDRESS(ROW()-1,COLUMN()))} -> vtuber_profiles | E4: {=INDIRECT(ADDRESS(ROW()-1,COLUMN()))} -> Vtuberプロフィール | F4: user_id | G4: ユーザーID | H4: uuid | I4: =_xlfn.LET( _xlpm.可変bit数,--MID(H4,FIND("(",H4)+1,FIND(")",H4)-FIND("(",H4)-1), _xlfn.XLOOKUP( $H4, 型とバイト数!$B$3:$B$54, 型とバイト数!$E$3:$E$54, IF(LEFT($H4,7)="varchar",_xlpm.可変bit数*8, IF(LEFT($H4,4)="char",_xlpm.可変bit数*8, IF(LEFT($H4,3)="bit",_xlpm.可変bit数,"???") ) ) ) ) -> 128 | K4: x | L4: users.users_uuid | M4: =_xlfn.SINGLE(IF(K4="","",IF(L4="","参照先未定義",_xlfn.XLOOKUP(L4,B:B,C:C,"エラー")))) -> 153 | Q4: 紐づけられたVtuberアカウント
A5: 〇 | B5: =D5&"."&F5 -> vtuber_profiles.join_group | C5: =ROW()-1 -> 4 | D5: {=INDIRECT(ADDRESS(ROW()-1,COLUMN()))} -> vtuber_profiles | E5: {=INDIRECT(ADDRESS(ROW()-1,COLUMN()))} -> Vtuberプロフィール | F5: join_group | G5: 所属 | H5: uuid | I5: =_xlfn.LET( _xlpm.可変bit数,--MID(H5,FIND("(",H5)+1,FIND(")",H5)-FIND("(",H5)-1), _xlfn.XLOOKUP( $H5, 型とバイト数!$B$3:$B$54, 型とバイト数!$E$3:$E$54, IF(LEFT($H5,7)="varchar",_xlpm.可変bit数*8, IF(LEFT($H5,4)="char",_xlpm.可変bit数*8, IF(LEFT($H5,3)="bit",_xlpm.可変bit数,"???") ) ) ) ) -> 128 | K5: x | L5: join_group.join_group_uuid | M5: =_xlfn.SINGLE(IF(K5="","",IF(L5="","参照先未定義",_xlfn.XLOOKUP(L5,B:B,C:C,"エラー")))) -> 12 | T5: x
A6: 〇 | B6: =D6&"."&F6 -> vtuber_profiles.debut_date | C6: =ROW()-1 -> 5 | D6: {=INDIRECT(ADDRESS(ROW()-1,COLUMN()))} -> vtuber_profiles | E6: {=INDIRECT(ADDRESS(ROW()-1,COLUMN()))} -> Vtuberプロフィール | F6: debut_date | G6: デビュー日 | H6: timestamptz | I6: =_xlfn.LET( _xlpm.可変bit数,--MID(H6,FIND("(",H6)+1,FIND(")",H6)-FIND("(",H6)-1), _xlfn.XLOOKUP( $H6, 型とバイト数!$B$3:$B$54, 型とバイト数!$E$3:$E$54, IF(LEFT($H6,7)="varchar",_xlpm.可変bit数*8, IF(LEFT($H6,4)="char",_xlpm.可変bit数*8, IF(LEFT($H6,3)="bit",_xlpm.可変bit数,"???") ) ) ) ) -> 64 | M6: =_xlfn.SINGLE(IF(K6="","",IF(L6="","参照先未定義",_xlfn.XLOOKUP(L6,B:B,C:C,"エラー")))) | T6: x
A7: 〇 | B7: =D7&"."&F7 -> vtuber_profiles.activity_status | C7: =ROW()-1 -> 6 | D7: {=INDIRECT(ADDRESS(ROW()-1,COLUMN()))} -> vtuber_profiles | E7: {=INDIRECT(ADDRESS(ROW()-1,COLUMN()))} -> Vtuberプロフィール | F7: activity_status | G7: 活動状態 | H7: uuid | I7: =_xlfn.LET( _xlpm.可変bit数,--MID(H7,FIND("(",H7)+1,FIND(")",H7)-FIND("(",H7)-1), _xlfn.XLOOKUP( $H7, 型とバイト数!$B$3:$B$54, 型とバイト数!$E$3:$E$54, IF(LEFT($H7,7)="varchar",_xlpm.可変bit数*8, IF(LEFT($H7,4)="char",_xlpm.可変bit数*8, IF(LEFT($H7,3)="bit",_xlpm.可変bit数,"???") ) ) ) ) -> 128 | K7: x | L7: activity_status.activity_status_uuid | M7: =_xlfn.SINGLE(IF(K7="","",IF(L7="","参照先未定義",_xlfn.XLOOKUP(L7,B:B,C:C,"エラー")))) -> 36 | N7: x
A8: 〇 | B8: =D8&"."&F8 -> vtuber_profiles.create_datetime | C8: =ROW()-1 -> 7 | D8: {=INDIRECT(ADDRESS(ROW()-1,COLUMN()))} -> vtuber_profiles | E8: {=INDIRECT(ADDRESS(ROW()-1,COLUMN()))} -> Vtuberプロフィール | F8: create_datetime | G8: 作成日 | H8: timestamptz | I8: =_xlfn.LET( _xlpm.可変bit数,--MID(H8,FIND("(",H8)+1,FIND(")",H8)-FIND("(",H8)-1), _xlfn.XLOOKUP( $H8, 型とバイト数!$B$3:$B$54, 型とバイト数!$E$3:$E$54, IF(LEFT($H8,7)="varchar",_xlpm.可変bit数*8, IF(LEFT($H8,4)="char",_xlpm.可変bit数*8, IF(LEFT($H8,3)="bit",_xlpm.可変bit数,"???") ) ) ) ) -> 64 | M8: =_xlfn.SINGLE(IF(K8="","",IF(L8="","参照先未定義",_xlfn.XLOOKUP(L8,B:B,C:C,"エラー")))) | N8: x | P8: CURRENT_TIMESTAMP
A9: 〇 | B9: =D9&"."&F9 -> vtuber_profiles.create_user | C9: =ROW()-1 -> 8 | D9: {=INDIRECT(ADDRESS(ROW()-1,COLUMN()))} -> vtuber_profiles | E9: {=INDIRECT(ADDRESS(ROW()-1,COLUMN()))} -> Vtuberプロフィール | F9: create_user | G9: 作成ユーザー | H9: varchar(32) | I9: =_xlfn.LET( _xlpm.可変bit数,--MID(H9,FIND("(",H9)+1,FIND(")",H9)-FIND("(",H9)-1), _xlfn.XLOOKUP( $H9, 型とバイト数!$B$3:$B$54, 型とバイト数!$E$3:$E$54, IF(LEFT($H9,7)="varchar",_xlpm.可変bit数*8, IF(LEFT($H9,4)="char",_xlpm.可変bit数*8, IF(LEFT($H9,3)="bit",_xlpm.可変bit数,"???") ) ) ) ) -> 256 | M9: =_xlfn.SINGLE(IF(K9="","",IF(L9="","参照先未定義",_xlfn.XLOOKUP(L9,B:B,C:C,"エラー")))) | N9: x | P9: CURRENT_USER | U9: 物理名を保存
A10: 〇 | B10: =D10&"."&F10 -> vtuber_profiles.update_datetime | C10: =ROW()-1 -> 9 | D10: {=INDIRECT(ADDRESS(ROW()-1,COLUMN()))} -> vtuber_profiles | E10: {=INDIRECT(ADDRESS(ROW()-1,COLUMN()))} -> Vtuberプロフィール | F10: update_datetime | G10: 更新日 | H10: timestamptz | I10: =_xlfn.LET( _xlpm.可変bit数,--MID(H10,FIND("(",H10)+1,FIND(")",H10)-FIND("(",H10)-1), _xlfn.XLOOKUP( $H10, 型とバイト数!$B$3:$B$54, 型とバイト数!$E$3:$E$54, IF(LEFT($H10,7)="varchar",_xlpm.可変bit数*8, IF(LEFT($H10,4)="char",_xlpm.可変bit数*8, IF(LEFT($H10,3)="bit",_xlpm.可変bit数,"???") ) ) ) ) -> 64 | M10: =_xlfn.SINGLE(IF(K10="","",IF(L10="","参照先未定義",_xlfn.XLOOKUP(L10,B:B,C:C,"エラー")))) | N10: x | P10: CURRENT_TIMESTAMP
A11: 〇 | B11: =D11&"."&F11 -> vtuber_profiles.update_user | C11: =ROW()-1 -> 10 | D11: {=INDIRECT(ADDRESS(ROW()-1,COLUMN()))} -> vtuber_profiles | E11: {=INDIRECT(ADDRESS(ROW()-1,COLUMN()))} -> Vtuberプロフィール | F11: update_user | G11: 更新ユーザー | H11: varchar(32) | I11: =_xlfn.LET( _xlpm.可変bit数,--MID(H11,FIND("(",H11)+1,FIND(")",H11)-FIND("(",H11)-1), _xlfn.XLOOKUP( $H11, 型とバイト数!$B$3:$B$54, 型とバイト数!$E$3:$E$54, IF(LEFT($H11,7)="varchar",_xlpm.可変bit数*8, IF(LEFT($H11,4)="char",_xlpm.可変bit数*8, IF(LEFT($H11,3)="bit",_xlpm.可変bit数,"???") ) ) ) ) -> 256 | M11: =_xlfn.SINGLE(IF(K11="","",IF(L11="","参照先未定義",_xlfn.XLOOKUP(L11,B:B,C:C,"エラー")))) | N11: x | P11: CURRENT_USER | U11: 物理名を保存
A12: 〇 | B12: =D12&"."&F12 -> vtuber_profiles.soft_delete_flag | C12: =ROW()-1 -> 11 | D12: {=INDIRECT(ADDRESS(ROW()-1,COLUMN()))} -> vtuber_profiles | E12: {=INDIRECT(ADDRESS(ROW()-1,COLUMN()))} -> Vtuberプロフィール | F12: soft_delete_flag | G12: 論理削除フラグ | H12: boolean | I12: =_xlfn.LET( _xlpm.可変bit数,--MID(H12,FIND("(",H12)+1,FIND(")",H12)-FIND("(",H12)-1), _xlfn.XLOOKUP( $H12, 型とバイト数!$B$3:$B$54, 型とバイト数!$E$3:$E$54, IF(LEFT($H12,7)="varchar",_xlpm.可変bit数*8, IF(LEFT($H12,4)="char",_xlpm.可変bit数*8, IF(LEFT($H12,3)="bit",_xlpm.可変bit数,"???") ) ) ) ) -> 8 | M12: =_xlfn.SINGLE(IF(K12="","",IF(L12="","参照先未定義",_xlfn.XLOOKUP(L12,B:B,C:C,"エラー")))) | N12: x | P12: 0
A13: 〇 | B13: =D13&"."&F13 -> join_group.join_group_uuid | C13: =ROW()-1 -> 12 | D13: join_group | E13: 所属 | F13: =D13&"_uuid" -> join_group_uuid | G13: UUID | H13: uuid | I13: =_xlfn.LET( _xlpm.可変bit数,--MID(H13,FIND("(",H13)+1,FIND(")",H13)-FIND("(",H13)-1), _xlfn.XLOOKUP( $H13, 型とバイト数!$B$3:$B$54, 型とバイト数!$E$3:$E$54, IF(LEFT($H13,7)="varchar",_xlpm.可変bit数*8, IF(LEFT($H13,4)="char",_xlpm.可変bit数*8, IF(LEFT($H13,3)="bit",_xlpm.可変bit数,"???") ) ) ) ) -> 128 | J13: x | M13: =_xlfn.SINGLE(IF(K13="","",IF(L13="","参照先未定義",_xlfn.XLOOKUP(L13,B:B,C:C,"エラー")))) | N13: x(PK制約) | O13: x(PK制約) | P13: gen_random_uuid()
A14: 〇 | B14: =D14&"."&F14 -> join_group.group_name | C14: =ROW()-1 -> 13 | D14: {=INDIRECT(ADDRESS(ROW()-1,COLUMN()))} -> join_group | E14: {=INDIRECT(ADDRESS(ROW()-1,COLUMN()))} -> 所属 | F14: group_name | G14: 所属名 | H14: varchar(64) | I14: =_xlfn.LET( _xlpm.可変bit数,--MID(H14,FIND("(",H14)+1,FIND(")",H14)-FIND("(",H14)-1), _xlfn.XLOOKUP( $H14, 型とバイト数!$B$3:$B$54, 型とバイト数!$E$3:$E$54, IF(LEFT($H14,7)="varchar",_xlpm.可変bit数*8, IF(LEFT($H14,4)="char",_xlpm.可変bit数*8, IF(LEFT($H14,3)="bit",_xlpm.可変bit数,"???") ) ) ) ) -> 512 | M14: =_xlfn.SINGLE(IF(K14="","",IF(L14="","参照先未定義",_xlfn.XLOOKUP(L14,B:B,C:C,"エラー")))) | N14: x | O14: x | T14: x
A15: 〇 | B15: =D15&"."&F15 -> join_group.operation_status | C15: =ROW()-1 -> 14 | D15: {=INDIRECT(ADDRESS(ROW()-1,COLUMN()))} -> join_group | E15: {=INDIRECT(ADDRESS(ROW()-1,COLUMN()))} -> 所属 | F15: operation_status | G15: 運営状態 | H15: uuid | I15: =_xlfn.LET( _xlpm.可変bit数,--MID(H15,FIND("(",H15)+1,FIND(")",H15)-FIND("(",H15)-1), _xlfn.XLOOKUP( $H15, 型とバイト数!$B$3:$B$54, 型とバイト数!$E$3:$E$54, IF(LEFT($H15,7)="varchar",_xlpm.可変bit数*8, IF(LEFT($H15,4)="char",_xlpm.可変bit数*8, IF(LEFT($H15,3)="bit",_xlpm.可変bit数,"???") ) ) ) ) -> 128 | K15: x | L15: activity_status.activity_status_uuid | M15: =_xlfn.SINGLE(IF(K15="","",IF(L15="","参照先未定義",_xlfn.XLOOKUP(L15,B:B,C:C,"エラー")))) -> 36
A16: 〇 | B16: =D16&"."&F16 -> join_group.group_detail | C16: =ROW()-1 -> 15 | D16: {=INDIRECT(ADDRESS(ROW()-1,COLUMN()))} -> join_group | E16: {=INDIRECT(ADDRESS(ROW()-1,COLUMN()))} -> 所属 | F16: group_detail | G16: 所属説明 | H16: text | I16: =_xlfn.LET( _xlpm.可変bit数,--MID(H16,FIND("(",H16)+1,FIND(")",H16)-FIND("(",H16)-1), _xlfn.XLOOKUP( $H16, 型とバイト数!$B$3:$B$54, 型とバイト数!$E$3:$E$54, IF(LEFT($H16,7)="varchar",_xlpm.可変bit数*8, IF(LEFT($H16,4)="char",_xlpm.可変bit数*8, IF(LEFT($H16,3)="bit",_xlpm.可変bit数,"???") ) ) ) ) -> - | M16: =_xlfn.SINGLE(IF(K16="","",IF(L16="","参照先未定義",_xlfn.XLOOKUP(L16,B:B,C:C,"エラー"))))
A17: 〇 | B17: =D17&"."&F17 -> join_group.create_datetime | C17: =ROW()-1 -> 16 | D17: {=INDIRECT(ADDRESS(ROW()-1,COLUMN()))} -> join_group | E17: {=INDIRECT(ADDRESS(ROW()-1,COLUMN()))} -> 所属 | F17: create_datetime | G17: 作成日 | H17: timestamptz | I17: =_xlfn.LET( _xlpm.可変bit数,--MID(H17,FIND("(",H17)+1,FIND(")",H17)-FIND("(",H17)-1), _xlfn.XLOOKUP( $H17, 型とバイト数!$B$3:$B$54, 型とバイト数!$E$3:$E$54, IF(LEFT($H17,7)="varchar",_xlpm.可変bit数*8, IF(LEFT($H17,4)="char",_xlpm.可変bit数*8, IF(LEFT($H17,3)="bit",_xlpm.可変bit数,"???") ) ) ) ) -> 64 | M17: =_xlfn.SINGLE(IF(K17="","",IF(L17="","参照先未定義",_xlfn.XLOOKUP(L17,B:B,C:C,"エラー")))) | N17: x | P17: CURRENT_TIMESTAMP
A18: 〇 | B18: =D18&"."&F18 -> join_group.create_user | C18: =ROW()-1 -> 17 | D18: {=INDIRECT(ADDRESS(ROW()-1,COLUMN()))} -> join_group | E18: {=INDIRECT(ADDRESS(ROW()-1,COLUMN()))} -> 所属 | F18: create_user | G18: 作成ユーザー | H18: varchar(32) | I18: =_xlfn.LET( _xlpm.可変bit数,--MID(H18,FIND("(",H18)+1,FIND(")",H18)-FIND("(",H18)-1), _xlfn.XLOOKUP( $H18, 型とバイト数!$B$3:$B$54, 型とバイト数!$E$3:$E$54, IF(LEFT($H18,7)="varchar",_xlpm.可変bit数*8, IF(LEFT($H18,4)="char",_xlpm.可変bit数*8, IF(LEFT($H18,3)="bit",_xlpm.可変bit数,"???") ) ) ) ) -> 256 | M18: =_xlfn.SINGLE(IF(K18="","",IF(L18="","参照先未定義",_xlfn.XLOOKUP(L18,B:B,C:C,"エラー")))) | N18: x | P18: CURRENT_USER | U18: 物理名を保存
A19: 〇 | B19: =D19&"."&F19 -> join_group.update_datetime | C19: =ROW()-1 -> 18 | D19: {=INDIRECT(ADDRESS(ROW()-1,COLUMN()))} -> join_group | E19: {=INDIRECT(ADDRESS(ROW()-1,COLUMN()))} -> 所属 | F19: update_datetime | G19: 更新日 | H19: timestamptz | I19: =_xlfn.LET( _xlpm.可変bit数,--MID(H19,FIND("(",H19)+1,FIND(")",H19)-FIND("(",H19)-1), _xlfn.XLOOKUP( $H19, 型とバイト数!$B$3:$B$54, 型とバイト数!$E$3:$E$54, IF(LEFT($H19,7)="varchar",_xlpm.可変bit数*8, IF(LEFT($H19,4)="char",_xlpm.可変bit数*8, IF(LEFT($H19,3)="bit",_xlpm.可変bit数,"???") ) ) ) ) -> 64 | M19: =_xlfn.SINGLE(IF(K19="","",IF(L19="","参照先未定義",_xlfn.XLOOKUP(L19,B:B,C:C,"エラー")))) | N19: x | P19: CURRENT_TIMESTAMP
A20: 〇 | B20: =D20&"."&F20 -> join_group.update_user | C20: =ROW()-1 -> 19 | D20: {=INDIRECT(ADDRESS(ROW()-1,COLUMN()))} -> join_group | E20: {=INDIRECT(ADDRESS(ROW()-1,COLUMN()))} -> 所属 | F20: update_user | G20: 更新ユーザー | H20: varchar(32) | I20: =_xlfn.LET( _xlpm.可変bit数,--MID(H20,FIND("(",H20)+1,FIND(")",H20)-FIND("(",H20)-1), _xlfn.XLOOKUP( $H20, 型とバイト数!$B$3:$B$54, 型とバイト数!$E$3:$E$54, IF(LEFT($H20,7)="varchar",_xlpm.可変bit数*8, IF(LEFT($H20,4)="char",_xlpm.可変bit数*8, IF(LEFT($H20,3)="bit",_xlpm.可変bit数,"???") ) ) ) ) -> 256 | M20: =_xlfn.SINGLE(IF(K20="","",IF(L20="","参照先未定義",_xlfn.XLOOKUP(L20,B:B,C:C,"エラー")))) | N20: x | P20: CURRENT_USER | U20: 物理名を保存
A21: 〇 | B21: =D21&"."&F21 -> join_group.soft_delete_flag | C21: =ROW()-1 -> 20 | D21: {=INDIRECT(ADDRESS(ROW()-1,COLUMN()))} -> join_group | E21: {=INDIRECT(ADDRESS(ROW()-1,COLUMN()))} -> 所属 | F21: soft_delete_flag | G21: 論理削除フラグ | H21: boolean | I21: =_xlfn.LET( _xlpm.可変bit数,--MID(H21,FIND("(",H21)+1,FIND(")",H21)-FIND("(",H21)-1), _xlfn.XLOOKUP( $H21, 型とバイト数!$B$3:$B$54, 型とバイト数!$E$3:$E$54, IF(LEFT($H21,7)="varchar",_xlpm.可変bit数*8, IF(LEFT($H21,4)="char",_xlpm.可変bit数*8, IF(LEFT($H21,3)="bit",_xlpm.可変bit数,"???") ) ) ) ) -> 8 | M21: =_xlfn.SINGLE(IF(K21="","",IF(L21="","参照先未定義",_xlfn.XLOOKUP(L21,B:B,C:C,"エラー")))) | N21: x | P21: 0
A22: 〇 | B22: =D22&"."&F22 -> tag.tag_uuid | C22: =ROW()-1 -> 21 | D22: tag | E22: タグ | F22: =D22&"_uuid" -> tag_uuid | G22: UUID | H22: uuid | I22: =_xlfn.LET( _xlpm.可変bit数,--MID(H22,FIND("(",H22)+1,FIND(")",H22)-FIND("(",H22)-1), _xlfn.XLOOKUP( $H22, 型とバイト数!$B$3:$B$54, 型とバイト数!$E$3:$E$54, IF(LEFT($H22,7)="varchar",_xlpm.可変bit数*8, IF(LEFT($H22,4)="char",_xlpm.可変bit数*8, IF(LEFT($H22,3)="bit",_xlpm.可変bit数,"???") ) ) ) ) -> 128 | J22: x | M22: =_xlfn.SINGLE(IF(K22="","",IF(L22="","参照先未定義",_xlfn.XLOOKUP(L22,B:B,C:C,"エラー")))) | N22: x(PK制約) | O22: x(PK制約) | P22: gen_random_uuid()
A23: 〇 | B23: =D23&"."&F23 -> tag.tag | C23: =ROW()-1 -> 22 | D23: {=INDIRECT(ADDRESS(ROW()-1,COLUMN()))} -> tag | E23: {=INDIRECT(ADDRESS(ROW()-1,COLUMN()))} -> タグ | F23: tag | G23: タグ名 | H23: text | I23: =_xlfn.LET( _xlpm.可変bit数,--MID(H23,FIND("(",H23)+1,FIND(")",H23)-FIND("(",H23)-1), _xlfn.XLOOKUP( $H23, 型とバイト数!$B$3:$B$54, 型とバイト数!$E$3:$E$54, IF(LEFT($H23,7)="varchar",_xlpm.可変bit数*8, IF(LEFT($H23,4)="char",_xlpm.可変bit数*8, IF(LEFT($H23,3)="bit",_xlpm.可変bit数,"???") ) ) ) ) -> - | M23: =_xlfn.SINGLE(IF(K23="","",IF(L23="","参照先未定義",_xlfn.XLOOKUP(L23,B:B,C:C,"エラー")))) | N23: x | O23: x | T23: x
A24: 〇 | B24: =D24&"."&F24 -> tag.create_datetime | C24: =ROW()-1 -> 23 | D24: {=INDIRECT(ADDRESS(ROW()-1,COLUMN()))} -> tag | E24: {=INDIRECT(ADDRESS(ROW()-1,COLUMN()))} -> タグ | F24: create_datetime | G24: 作成日 | H24: timestamptz | I24: =_xlfn.LET( _xlpm.可変bit数,--MID(H24,FIND("(",H24)+1,FIND(")",H24)-FIND("(",H24)-1), _xlfn.XLOOKUP( $H24, 型とバイト数!$B$3:$B$54, 型とバイト数!$E$3:$E$54, IF(LEFT($H24,7)="varchar",_xlpm.可変bit数*8, IF(LEFT($H24,4)="char",_xlpm.可変bit数*8, IF(LEFT($H24,3)="bit",_xlpm.可変bit数,"???") ) ) ) ) -> 64 | M24: =_xlfn.SINGLE(IF(K24="","",IF(L24="","参照先未定義",_xlfn.XLOOKUP(L24,B:B,C:C,"エラー")))) | N24: x | P24: CURRENT_TIMESTAMP
A25: 〇 | B25: =D25&"."&F25 -> tag.create_user | C25: =ROW()-1 -> 24 | D25: {=INDIRECT(ADDRESS(ROW()-1,COLUMN()))} -> tag | E25: {=INDIRECT(ADDRESS(ROW()-1,COLUMN()))} -> タグ | F25: create_user | G25: 作成ユーザー | H25: varchar(32) | I25: =_xlfn.LET( _xlpm.可変bit数,--MID(H25,FIND("(",H25)+1,FIND(")",H25)-FIND("(",H25)-1), _xlfn.XLOOKUP( $H25, 型とバイト数!$B$3:$B$54, 型とバイト数!$E$3:$E$54, IF(LEFT($H25,7)="varchar",_xlpm.可変bit数*8, IF(LEFT($H25,4)="char",_xlpm.可変bit数*8, IF(LEFT($H25,3)="bit",_xlpm.可変bit数,"???") ) ) ) ) -> 256 | M25: =_xlfn.SINGLE(IF(K25="","",IF(L25="","参照先未定義",_xlfn.XLOOKUP(L25,B:B,C:C,"エラー")))) | N25: x | P25: CURRENT_USER | U25: 物理名を保存
A26: 〇 | B26: =D26&"."&F26 -> tag.update_datetime | C26: =ROW()-1 -> 25 | D26: {=INDIRECT(ADDRESS(ROW()-1,COLUMN()))} -> tag | E26: {=INDIRECT(ADDRESS(ROW()-1,COLUMN()))} -> タグ | F26: update_datetime | G26: 更新日 | H26: timestamptz | I26: =_xlfn.LET( _xlpm.可変bit数,--MID(H26,FIND("(",H26)+1,FIND(")",H26)-FIND("(",H26)-1), _xlfn.XLOOKUP( $H26, 型とバイト数!$B$3:$B$54, 型とバイト数!$E$3:$E$54, IF(LEFT($H26,7)="varchar",_xlpm.可変bit数*8, IF(LEFT($H26,4)="char",_xlpm.可変bit数*8, IF(LEFT($H26,3)="bit",_xlpm.可変bit数,"???") ) ) ) ) -> 64 | M26: =_xlfn.SINGLE(IF(K26="","",IF(L26="","参照先未定義",_xlfn.XLOOKUP(L26,B:B,C:C,"エラー")))) | N26: x | P26: CURRENT_TIMESTAMP
A27: 〇 | B27: =D27&"."&F27 -> tag.update_user | C27: =ROW()-1 -> 26 | D27: {=INDIRECT(ADDRESS(ROW()-1,COLUMN()))} -> tag | E27: {=INDIRECT(ADDRESS(ROW()-1,COLUMN()))} -> タグ | F27: update_user | G27: 更新ユーザー | H27: varchar(32) | I27: =_xlfn.LET( _xlpm.可変bit数,--MID(H27,FIND("(",H27)+1,FIND(")",H27)-FIND("(",H27)-1), _xlfn.XLOOKUP( $H27, 型とバイト数!$B$3:$B$54, 型とバイト数!$E$3:$E$54, IF(LEFT($H27,7)="varchar",_xlpm.可変bit数*8, IF(LEFT($H27,4)="char",_xlpm.可変bit数*8, IF(LEFT($H27,3)="bit",_xlpm.可変bit数,"???") ) ) ) ) -> 256 | M27: =_xlfn.SINGLE(IF(K27="","",IF(L27="","参照先未定義",_xlfn.XLOOKUP(L27,B:B,C:C,"エラー")))) | N27: x | P27: CURRENT_USER | U27: 物理名を保存
A28: 〇 | B28: =D28&"."&F28 -> tag.soft_delete_flag | C28: =ROW()-1 -> 27 | D28: {=INDIRECT(ADDRESS(ROW()-1,COLUMN()))} -> tag | E28: {=INDIRECT(ADDRESS(ROW()-1,COLUMN()))} -> タグ | F28: soft_delete_flag | G28: 論理削除フラグ | H28: boolean | I28: =_xlfn.LET( _xlpm.可変bit数,--MID(H28,FIND("(",H28)+1,FIND(")",H28)-FIND("(",H28)-1), _xlfn.XLOOKUP( $H28, 型とバイト数!$B$3:$B$54, 型とバイト数!$E$3:$E$54, IF(LEFT($H28,7)="varchar",_xlpm.可変bit数*8, IF(LEFT($H28,4)="char",_xlpm.可変bit数*8, IF(LEFT($H28,3)="bit",_xlpm.可変bit数,"???") ) ) ) ) -> 8 | M28: =_xlfn.SINGLE(IF(K28="","",IF(L28="","参照先未定義",_xlfn.XLOOKUP(L28,B:B,C:C,"エラー")))) | N28: x | P28: 0
A29: 〇 | B29: =D29&"."&F29 -> badge.badge_uuid | C29: =ROW()-1 -> 28 | D29: badge | E29: バッジ | F29: =D29&"_uuid" -> badge_uuid | G29: UUID | H29: uuid | I29: =_xlfn.LET( _xlpm.可変bit数,--MID(H29,FIND("(",H29)+1,FIND(")",H29)-FIND("(",H29)-1), _xlfn.XLOOKUP( $H29, 型とバイト数!$B$3:$B$54, 型とバイト数!$E$3:$E$54, IF(LEFT($H29,7)="varchar",_xlpm.可変bit数*8, IF(LEFT($H29,4)="char",_xlpm.可変bit数*8, IF(LEFT($H29,3)="bit",_xlpm.可変bit数,"???") ) ) ) ) -> 128 | J29: x | M29: =_xlfn.SINGLE(IF(K29="","",IF(L29="","参照先未定義",_xlfn.XLOOKUP(L29,B:B,C:C,"エラー")))) | N29: x(PK制約) | O29: x(PK制約) | P29: gen_random_uuid()
A30: 〇 | B30: =D30&"."&F30 -> badge.badge_physical_name | C30: =ROW()-1 -> 29 | D30: {=INDIRECT(ADDRESS(ROW()-1,COLUMN()))} -> badge | E30: {=INDIRECT(ADDRESS(ROW()-1,COLUMN()))} -> バッジ | F30: badge_physical_name | G30: バッジ名(物理名) | H30: varchar(24) | I30: =_xlfn.LET( _xlpm.可変bit数,--MID(H30,FIND("(",H30)+1,FIND(")",H30)-FIND("(",H30)-1), _xlfn.XLOOKUP( $H30, 型とバイト数!$B$3:$B$54, 型とバイト数!$E$3:$E$54, IF(LEFT($H30,7)="varchar",_xlpm.可変bit数*8, IF(LEFT($H30,4)="char",_xlpm.可変bit数*8, IF(LEFT($H30,3)="bit",_xlpm.可変bit数,"???") ) ) ) ) -> 192 | M30: =_xlfn.SINGLE(IF(K30="","",IF(L30="","参照先未定義",_xlfn.XLOOKUP(L30,B:B,C:C,"エラー")))) | N30: x | O30: x | T30: x
A31: 〇 | B31: =D31&"."&F31 -> badge.badge_logical_name | C31: =ROW()-1 -> 30 | D31: {=INDIRECT(ADDRESS(ROW()-1,COLUMN()))} -> badge | E31: {=INDIRECT(ADDRESS(ROW()-1,COLUMN()))} -> バッジ | F31: badge_logical_name | G31: バッジ名(論理名) | H31: varchar(24) | I31: =_xlfn.LET( _xlpm.可変bit数,--MID(H31,FIND("(",H31)+1,FIND(")",H31)-FIND("(",H31)-1), _xlfn.XLOOKUP( $H31, 型とバイト数!$B$3:$B$54, 型とバイト数!$E$3:$E$54, IF(LEFT($H31,7)="varchar",_xlpm.可変bit数*8, IF(LEFT($H31,4)="char",_xlpm.可変bit数*8, IF(LEFT($H31,3)="bit",_xlpm.可変bit数,"???") ) ) ) ) -> 192 | M31: =_xlfn.SINGLE(IF(K31="","",IF(L31="","参照先未定義",_xlfn.XLOOKUP(L31,B:B,C:C,"エラー")))) | T31: x | U31: 多言語化対応で削除予定。よく見られているVtuber、新人Vtuber、最近更新されたVTuber
A32: 〇 | B32: =D32&"."&F32 -> badge.create_datetime | C32: =ROW()-1 -> 31 | D32: {=INDIRECT(ADDRESS(ROW()-1,COLUMN()))} -> badge | E32: {=INDIRECT(ADDRESS(ROW()-1,COLUMN()))} -> バッジ | F32: create_datetime | G32: 作成日 | H32: timestamptz | I32: =_xlfn.LET( _xlpm.可変bit数,--MID(H32,FIND("(",H32)+1,FIND(")",H32)-FIND("(",H32)-1), _xlfn.XLOOKUP( $H32, 型とバイト数!$B$3:$B$54, 型とバイト数!$E$3:$E$54, IF(LEFT($H32,7)="varchar",_xlpm.可変bit数*8, IF(LEFT($H32,4)="char",_xlpm.可変bit数*8, IF(LEFT($H32,3)="bit",_xlpm.可変bit数,"???") ) ) ) ) -> 64 | M32: =_xlfn.SINGLE(IF(K32="","",IF(L32="","参照先未定義",_xlfn.XLOOKUP(L32,B:B,C:C,"エラー")))) | N32: x | P32: CURRENT_TIMESTAMP
A33: 〇 | B33: =D33&"."&F33 -> badge.create_user | C33: =ROW()-1 -> 32 | D33: {=INDIRECT(ADDRESS(ROW()-1,COLUMN()))} -> badge | E33: {=INDIRECT(ADDRESS(ROW()-1,COLUMN()))} -> バッジ | F33: create_user | G33: 作成ユーザー | H33: varchar(32) | I33: =_xlfn.LET( _xlpm.可変bit数,--MID(H33,FIND("(",H33)+1,FIND(")",H33)-FIND("(",H33)-1), _xlfn.XLOOKUP( $H33, 型とバイト数!$B$3:$B$54, 型とバイト数!$E$3:$E$54, IF(LEFT($H33,7)="varchar",_xlpm.可変bit数*8, IF(LEFT($H33,4)="char",_xlpm.可変bit数*8, IF(LEFT($H33,3)="bit",_xlpm.可変bit数,"???") ) ) ) ) -> 256 | M33: =_xlfn.SINGLE(IF(K33="","",IF(L33="","参照先未定義",_xlfn.XLOOKUP(L33,B:B,C:C,"エラー")))) | N33: x | P33: CURRENT_USER | U33: 物理名を保存
A34: 〇 | B34: =D34&"."&F34 -> badge.update_datetime | C34: =ROW()-1 -> 33 | D34: {=INDIRECT(ADDRESS(ROW()-1,COLUMN()))} -> badge | E34: {=INDIRECT(ADDRESS(ROW()-1,COLUMN()))} -> バッジ | F34: update_datetime | G34: 更新日 | H34: timestamptz | I34: =_xlfn.LET( _xlpm.可変bit数,--MID(H34,FIND("(",H34)+1,FIND(")",H34)-FIND("(",H34)-1), _xlfn.XLOOKUP( $H34, 型とバイト数!$B$3:$B$54, 型とバイト数!$E$3:$E$54, IF(LEFT($H34,7)="varchar",_xlpm.可変bit数*8, IF(LEFT($H34,4)="char",_xlpm.可変bit数*8, IF(LEFT($H34,3)="bit",_xlpm.可変bit数,"???") ) ) ) ) -> 64 | M34: =_xlfn.SINGLE(IF(K34="","",IF(L34="","参照先未定義",_xlfn.XLOOKUP(L34,B:B,C:C,"エラー")))) | N34: x | P34: CURRENT_TIMESTAMP
A35: 〇 | B35: =D35&"."&F35 -> badge.update_user | C35: =ROW()-1 -> 34 | D35: {=INDIRECT(ADDRESS(ROW()-1,COLUMN()))} -> badge | E35: {=INDIRECT(ADDRESS(ROW()-1,COLUMN()))} -> バッジ | F35: update_user | G35: 更新ユーザー | H35: varchar(32) | I35: =_xlfn.LET( _xlpm.可変bit数,--MID(H35,FIND("(",H35)+1,FIND(")",H35)-FIND("(",H35)-1), _xlfn.XLOOKUP( $H35, 型とバイト数!$B$3:$B$54, 型とバイト数!$E$3:$E$54, IF(LEFT($H35,7)="varchar",_xlpm.可変bit数*8, IF(LEFT($H35,4)="char",_xlpm.可変bit数*8, IF(LEFT($H35,3)="bit",_xlpm.可変bit数,"???") ) ) ) ) -> 256 | M35: =_xlfn.SINGLE(IF(K35="","",IF(L35="","参照先未定義",_xlfn.XLOOKUP(L35,B:B,C:C,"エラー")))) | N35: x | P35: CURRENT_USER | U35: 物理名を保存
A36: 〇 | B36: =D36&"."&F36 -> badge.soft_delete_flag | C36: =ROW()-1 -> 35 | D36: {=INDIRECT(ADDRESS(ROW()-1,COLUMN()))} -> badge | E36: {=INDIRECT(ADDRESS(ROW()-1,COLUMN()))} -> バッジ | F36: soft_delete_flag | G36: 論理削除フラグ | H36: boolean | I36: =_xlfn.LET( _xlpm.可変bit数,--MID(H36,FIND("(",H36)+1,FIND(")",H36)-FIND("(",H36)-1), _xlfn.XLOOKUP( $H36, 型とバイト数!$B$3:$B$54, 型とバイト数!$E$3:$E$54, IF(LEFT($H36,7)="varchar",_xlpm.可変bit数*8, IF(LEFT($H36,4)="char",_xlpm.可変bit数*8, IF(LEFT($H36,3)="bit",_xlpm.可変bit数,"???") ) ) ) ) -> 8 | M36: =_xlfn.SINGLE(IF(K36="","",IF(L36="","参照先未定義",_xlfn.XLOOKUP(L36,B:B,C:C,"エラー")))) | N36: x | P36: 0
A37: 〇 | B37: =D37&"."&F37 -> activity_status.activity_status_uuid | C37: =ROW()-1 -> 36 | D37: activity_status | E37: 活動状態 | F37: =D37&"_uuid" -> activity_status_uuid | G37: UUID | H37: uuid | I37: =_xlfn.LET( _xlpm.可変bit数,--MID(H37,FIND("(",H37)+1,FIND(")",H37)-FIND("(",H37)-1), _xlfn.XLOOKUP( $H37, 型とバイト数!$B$3:$B$54, 型とバイト数!$E$3:$E$54, IF(LEFT($H37,7)="varchar",_xlpm.可変bit数*8, IF(LEFT($H37,4)="char",_xlpm.可変bit数*8, IF(LEFT($H37,3)="bit",_xlpm.可変bit数,"???") ) ) ) ) -> 128 | J37: x | M37: =_xlfn.SINGLE(IF(K37="","",IF(L37="","参照先未定義",_xlfn.XLOOKUP(L37,B:B,C:C,"エラー")))) | N37: x(PK制約) | O37: x(PK制約) | P37: gen_random_uuid()
A38: 〇 | B38: =D38&"."&F38 -> activity_status.activity_status_physical_name | C38: =ROW()-1 -> 37 | D38: {=INDIRECT(ADDRESS(ROW()-1,COLUMN()))} -> activity_status | E38: {=INDIRECT(ADDRESS(ROW()-1,COLUMN()))} -> 活動状態 | F38: activity_status_physical_name | G38: 活動状態名(物理名) | H38: varchar(8) | I38: =_xlfn.LET( _xlpm.可変bit数,--MID(H38,FIND("(",H38)+1,FIND(")",H38)-FIND("(",H38)-1), _xlfn.XLOOKUP( $H38, 型とバイト数!$B$3:$B$54, 型とバイト数!$E$3:$E$54, IF(LEFT($H38,7)="varchar",_xlpm.可変bit数*8, IF(LEFT($H38,4)="char",_xlpm.可変bit数*8, IF(LEFT($H38,3)="bit",_xlpm.可変bit数,"???") ) ) ) ) -> 64 | M38: =_xlfn.SINGLE(IF(K38="","",IF(L38="","参照先未定義",_xlfn.XLOOKUP(L38,B:B,C:C,"エラー")))) | N38: x | O38: x
A39: 〇 | B39: =D39&"."&F39 -> activity_status.activity_status_logical_name | C39: =ROW()-1 -> 38 | D39: {=INDIRECT(ADDRESS(ROW()-1,COLUMN()))} -> activity_status | E39: {=INDIRECT(ADDRESS(ROW()-1,COLUMN()))} -> 活動状態 | F39: activity_status_logical_name | G39: 活動状態名(論理名) | H39: varchar(8) | I39: =_xlfn.LET( _xlpm.可変bit数,--MID(H39,FIND("(",H39)+1,FIND(")",H39)-FIND("(",H39)-1), _xlfn.XLOOKUP( $H39, 型とバイト数!$B$3:$B$54, 型とバイト数!$E$3:$E$54, IF(LEFT($H39,7)="varchar",_xlpm.可変bit数*8, IF(LEFT($H39,4)="char",_xlpm.可変bit数*8, IF(LEFT($H39,3)="bit",_xlpm.可変bit数,"???") ) ) ) ) -> 64 | M39: =_xlfn.SINGLE(IF(K39="","",IF(L39="","参照先未定義",_xlfn.XLOOKUP(L39,B:B,C:C,"エラー")))) | U39: 多言語化対応で削除予定。活動開始前(VTuber準備中)、活動中、卒業済み
A40: 〇 | B40: =D40&"."&F40 -> activity_status.create_datetime | C40: =ROW()-1 -> 39 | D40: {=INDIRECT(ADDRESS(ROW()-1,COLUMN()))} -> activity_status | E40: {=INDIRECT(ADDRESS(ROW()-1,COLUMN()))} -> 活動状態 | F40: create_datetime | G40: 作成日 | H40: timestamptz | I40: =_xlfn.LET( _xlpm.可変bit数,--MID(H40,FIND("(",H40)+1,FIND(")",H40)-FIND("(",H40)-1), _xlfn.XLOOKUP( $H40, 型とバイト数!$B$3:$B$54, 型とバイト数!$E$3:$E$54, IF(LEFT($H40,7)="varchar",_xlpm.可変bit数*8, IF(LEFT($H40,4)="char",_xlpm.可変bit数*8, IF(LEFT($H40,3)="bit",_xlpm.可変bit数,"???") ) ) ) ) -> 64 | M40: =_xlfn.SINGLE(IF(K40="","",IF(L40="","参照先未定義",_xlfn.XLOOKUP(L40,B:B,C:C,"エラー")))) | N40: x | P40: CURRENT_TIMESTAMP
...

Sheet 型とバイト数
A1: https://qiita.com/hk_arc/items/0474d28bc8620571db3c
A2: カテゴリ | B2: データ型 | C2: 格納サイズ | D2: 格納サイズ(byte) | E2: 格納サイズ(bit) | F2: 範囲 | G2: 用途例
A3: 数値型 | B3: smallint | C3: 2バイト | D3: 2 | E3: =IF(D3<>"-",D3*8,"-") -> 16 | F3: -32,768 から +32,767 | G3: 小規模なIDやカウンターに適用
A4: 数値型 | B4: integer | C4: 4バイト | D4: 4 | E4: =IF(D4<>"-",D4*8,"-") -> 32 | F4: -2,147,483,648 から +2,147,483,647 | G4: 一般的な数値計算や中規模のIDに使用
A5: 数値型 | B5: bigint | C5: 8バイト | D5: 8 | E5: =IF(D5<>"-",D5*8,"-") -> 64 | F5: -9,223,372,036,854,775,808 から 9,223,372,036,854,775,807 | G5: 大規模なデータベースのIDや大規模な数値計算に使用
A6: 数値型 | B6: decimal | C6: 可変長 | D6: - | E6: =IF(D6<>"-",D6*8,"-") -> - | F6: 小数点前までは131072桁、小数点以降は16383桁 | G6: 金融取引や高精度計算に使用
A7: 数値型 | B7: numeric | C7: 可変長 | D7: - | E7: =IF(D7<>"-",D7*8,"-") -> - | F7: 小数点前までは131072桁、小数点以降は16383桁 | G7: 同上
A8: 数値型 | B8: real | C8: 4バイト | D8: 4 | E8: =IF(D8<>"-",D8*8,"-") -> 32 | F8: 6桁精度 | G8: 科学技術計算での近似値計算に使用
A9: 数値型 | B9: double precision | C9: 8バイト | D9: 8 | E9: =IF(D9<>"-",D9*8,"-") -> 64 | F9: 15桁精度 | G9: 高精度な科学技術計算に使用
A10: 数値型 | B10: smallserial | C10: 2バイト | D10: 2 | E10: =IF(D10<>"-",D10*8,"-") -> 16 | F10: 1から32,767 | G10: 自動生成される小規模な連続IDに使用
A11: 数値型 | B11: serial | C11: 4バイト | D11: 4 | E11: =IF(D11<>"-",D11*8,"-") -> 32 | F11: 1から2,147,483,647 | G11: 自動生成される中規模の連続IDに使用
A12: 数値型 | B12: bigserial | C12: 8バイト | D12: 8 | E12: =IF(D12<>"-",D12*8,"-") -> 64 | F12: 1から9,223,372,036,854,775,807 | G12: 自動生成される大規模な連続IDに使用
A13: 通貨型 | B13: money | C13: 8バイト | D13: 8 | E13: =IF(D13<>"-",D13*8,"-") -> 64 | F13: -922,337,203,685,477.5808 から 922,337,203,685,477.5807 | G13: 金融取引の金額や費用の格納に使用
A14: 文字列型 | B14: character(n), char(n) | C14: nバイト | D14: - | E14: =IF(D14<>"-",D14*8,"-") -> - | F14: 固定長n文字 | G14: 固定長のデータ、例えば性別、国コードなど
A15: 文字列型 | B15: character varying(n), varchar(n) | C15: 最大nバイト | D15: - | E15: =IF(D15<>"-",D15*8,"-") -> - | F15: 最大n文字 | G15: 可変長データ、例えば名前、住所など
A16: 文字列型 | B16: text | C16: 可変長 | D16: - | E16: =IF(D16<>"-",D16*8,"-") -> - | F16: 無制限 | G16: 長いテキストデータ、例えば記事内容、コメント
A17: 日付/時刻型 | B17: timestamp [ (p) ] [ without time zone ] | C17: 8バイト | D17: 8 | E17: =IF(D17<>"-",D17*8,"-") -> 64 | F17: 4713 BCから294276 AD | G17: 歴史的または将来のイベントの日時の記録
A18: 日付/時刻型 | B18: timestamp [ (p) ] with time zone | C18: 8バイト | D18: 8 | E18: =IF(D18<>"-",D18*8,"-") -> 64 | F18: 4713 BCから294276 AD | G18: グローバルで発生するイベントの時間を地域別に記録
A19: 日付/時刻型 | B19: timestamp | C19: 8バイト | D19: 8 | E19: =IF(D19<>"-",D19*8,"-") -> 64 | G19: テーブル一覧でバイト数を計算する用。実際はtimestamp [ (p) ] [ without time zone ]
A20: 日付/時刻型 | B20: timestamptz | C20: 8バイト | D20: 8 | E20: =IF(D20<>"-",D20*8,"-") -> 64 | G20: テーブル一覧でバイト数を計算する用。実際はtimestamp [ (p) ] [ without time zone ]
A21: 日付/時刻型 | B21: date | C21: 4バイト | D21: 4 | E21: =IF(D21<>"-",D21*8,"-") -> 32 | F21: 4713 BCから5874897 AD | G21: 日付のみが必要な場合（例：生年月日）
A22: 日付/時刻型 | B22: time [ (p) ] [ without time zone ] | C22: 8バイト | D22: 8 | E22: =IF(D22<>"-",D22*8,"-") -> 64 | F22: 00:00:00から24:00:00 | G22: 日々のスケジュールや業務時間の管理
A23: 日付/時刻型 | B23: time [ (p) ] with time zone | C23: 12バイト | D23: 12 | E23: =IF(D23<>"-",D23*8,"-") -> 96 | F23: 00:00:00+1459から24:00:00-1459 | G23: タイムゾーンを考慮した正確な時刻記録
A24: 日付/時刻型 | B24: interval [ fields ] [ (p) ] | C24: 12バイト | D24: 12 | E24: =IF(D24<>"-",D24*8,"-") -> 96 | F24: -178000000年から178000000年 | G24: 時間の経過、期間の測定（例：保証期間、契約期間）
A25: 論理型 | B25: boolean | C25: 1バイト | D25: 1 | E25: =IF(D25<>"-",D25*8,"-") -> 8 | F25: true/false | G25: フラグ、条件式の結果
A26: JSON型 | B26: json | C26: 可変長 | D26: - | E26: =IF(D26<>"-",D26*8,"-") -> - | F26: 無制限 | G26: 設定データ、動的フォームデータ
A27: JSON型 | B27: jsonb | C27: 可変長 | D27: - | E27: =IF(D27<>"-",D27*8,"-") -> - | F27: 無制限 | G27: インデックス付きJSONデータ
A28: 幾何データ型 | B28: point | C28: 16バイト | D28: 16 | E28: =IF(D28<>"-",D28*8,"-") -> 128 | F28: (x, y) | G28: 地図上の特定の位置を表す
A29: 幾何データ型 | B29: line | C29: 32バイト | D29: 32 | E29: =IF(D29<>"-",D29*8,"-") -> 256 | F29: ((x1, y1), (x2, y2)) | G29: 無限に伸びる直線を表現（完全には実装されていない）
A30: 幾何データ型 | B30: lseg | C30: 32バイト | D30: 32 | E30: =IF(D30<>"-",D30*8,"-") -> 256 | F30: ((x1, y1), (x2, y2)) | G30: 有限の線分を表す
A31: 幾何データ型 | B31: box | C31: 32バイト | D31: 32 | E31: =IF(D31<>"-",D31*8,"-") -> 256 | F31: ((x1, y1), (x2, y2)) | G31: 矩形を表現するために使用
A32: 幾何データ型 | B32: path | C32: 16 + 16nバイト | D32: - | E32: =IF(D32<>"-",D32*8,"-") -> - | F32: 閉経路：((x1, y1), ...) | G32: 閉じた多角形のパスを表現する
A33: 幾何データ型 | B33: path | C33: 16 + 16nバイト | D33: - | E33: =IF(D33<>"-",D33*8,"-") -> - | F33: 開経路：[(x1, y1), ...] | G33: 開いた経路のパスを表現する
A34: 幾何データ型 | B34: polygon | C34: 40 + 16nバイト | D34: - | E34: =IF(D34<>"-",D34*8,"-") -> - | F34: ((x1, y1), ...) | G34: 多角形を表現する
A35: 幾何データ型 | B35: circle | C35: 24バイト | D35: 24 | E35: =IF(D35<>"-",D35*8,"-") -> 192 | F35: <(x, y), r>（中心と半径） | G35: 円を表現するために使用
A36: ネットワーク型 | B36: cidr | C36: 7もしくは19バイト | D36: - | E36: =IF(D36<>"-",D36*8,"-") -> - | F36: IPv4、およびIPv6ネットワーク | G36: IPアドレスブロックの管理、ネットワーク計画
A37: ネットワーク型 | B37: inet | C37: 7もしくは19バイト | D37: - | E37: =IF(D37<>"-",D37*8,"-") -> - | F37: IPv4もしくはIPv6ホスト、およびネットワーク | G37: 個別のIPアドレスおよびそのネットワークマスクの記録
A38: ネットワーク型 | B38: macaddr | C38: 6バイト | D38: 6 | E38: =IF(D38<>"-",D38*8,"-") -> 48 | F38: MACアドレス | G38: ネットワークハードウェアの識別
A39: ビット列型 | B39: bit(n) | C39: nビット | D39: - | E39: =IF(D39<>"-",D39*8,"-") -> - | F39: 固定長nビット | G39: フラグ、ビットマスク、固定長ビットデータの格納
A40: ビット列型 | B40: bit varying(n) | C40: 最大nビット | D40: - | E40: =IF(D40<>"-",D40*8,"-") -> - | F40: 可変長最大nビット | G40: 可変長のビットデータの格納
...
